# 45장 - 프로미스

## 비동기 처리를 위한 콜백 패턴의 단점

### 콜백 헬 발생

- 비동기 함수의 처리 결과에 대한 후속 처리는 콜백 함수로 하는 것이 일반적이다.
- 비동기 함수의 후속 처리 결과를 가지고 또다시 비동기 함수를 호출한다면 콜백 함수의 중첩도가 높아지는 **콜백 헬**이 발생한다.

```jsx
// 콜백 헬 예시
get('/step1', a => {
	get(`/step2/${a}`, b => {
			get(`/step3/${b}`, c => {
				get(`/step4/${c}`, d => {
					console.log(d);
			})
		})
	})
})
```

### 에러 처리의 한계

- 비동기 처리를 위한 콜백 패턴의 문제점 중에 가장 심각한 것은 에러 처리가 곤란하다는 것이다.

```jsx
// catch 블록에서 에러를 캐치하지 못한다.
try {
	setTimeout(() => {throw new Erro('Error!');}, 1000);
} catch(e) {
	console.error('캐치한 에러', e);
}
```

- setTimeout 함수의 콜백 함수가 실행될 때 setTimeout 함수는 이미 콜 스택에서 제거된 상태다.
    
    이것은 setTimeout 함수의 콜백 함수를 호출한 것이 setTimeout함수가 아니라는 것을 의미한다.
    
- 에러는 호출자 방향으로 전파된다.
- 따라서 setTimeout 함수의 콜백 함수가 발생시킨 에러는 catch 블록에서 캐치되지 않는다.

<aside>
💡 위와 같은 문제를 극복하기 위해 ES6에서 Promise가 도입되었다.

</aside>

## 프로미스의 생성

- new 연산자와 함께 Promise 객체를 생성하여 사용한다.
- 인자로 비동기 처리를 수행할 콜백함수를 받는다.
- 콜백함수의 인자로 resolve와 reject 함수를 받는다.
- resolve 함수는 비동기 처리가 성공하면 결과를 인수로 전달하여 호출하고
- reject 함수는 비동기 처리가 실패하면 에러를 인수로 전달하면서 호출한다.

```jsx
const promise = new Promise((resolve, reject) => {
	if(/* 비동기 처리 성공*/) {
		resolve('result');
	} else { /* 비동기 처리 실패 */
		reject('failure reason');
	}
});
```

### 프로미스의 상태 정보

| 상태 | 의미 | 상태 변경 조건 |
| --- | --- | --- |
| pending | 비동기 처리가 아직 수행되지 않은 상태 | 프로미스가 생성된 직후 기본 상태 |
| fulfilled | 비동기 처리가 수행된 상태(성공) | resolve함수 호출 |
| rejected | 비동기 처리가 수행된 상태(실패) | reject 함수 호출 |
| settled | pending이 아닌 비동기 처리가 수행된 상태 | fulfilled나 rejected된 상태 |
- 비동기 처리 성공 : resolve 함수를 호출해 프로미스를 fulfilled상태로 변경
- 비동기 처리 실패 : reject 함수를 호출해 프로미스를 rejected 상태로 변경

<aside>
💡 프로미스는 비동기 처리 상태와 처리 결과를 관리하는 객체다.

</aside>

## 프로미스의 후속 처리 메서드

- 프로미스의 비동기 처리 상태가 변화하면 이에 따른 후속 처리를 해야 한다.
- 프로미스의 비동기 처리 상태가 변화하면 후속 처리 메서드에 인수로 전달한 콜백 함수가 선택적으로 호출된다.
- 후속 처리 메서드의 콜백 함수에 프로미스 처리 결과가 인수로 전달된다.

### Promise.prototype.then

- then 메서드는 두 개의 콜백 함수를 인수로 전달받는다.
- 첫 번째 콜백 함수는 비동기 처리가 성공했을 때 호출되는 성공 처리 콜백함수
- 두 번째 콜백 함수는 비동기 처리가 실패했을 때 호출되는 실패 처리 콜백함수
- then 메서드는 프로미스를 반환한다.

### Promise.prototype.catch

- catch 메서드는 한 개의 콜백  함수를 인수로 전달받는다.
- catch메서드의 콜백함수는 프로미스가 rejected 상태인 경우만 호출된다.
- catch 메서드는 프로미스를 반환한다.

### Promise.prototype.finally

- finally 메서드는 한 개의 콜백 함수를 인자로 전달받는다.
- finally 메서드의 콜백 함수는 프로미스의 성공(fulfiled) 또는 실패(rejected)와 상관없이 무조건 한 번 호출된다.
- finally 메서드는 프로미스의 상태와 상관없이 공통적으로 수행해야 할 일이 있을 때 유용하다
- finally 메서드는 프로미스를 반환한다.

## 프로미스의 에러 처리

- 비동기 처리에서 발생한 에러는 then메서드의 두 번째 콜백 함수로 처리할 수 있다.

```jsx
const wrongUrl = 'https://jsonplaceholder.typicode.com/XXX/1';

promiseGet(wrongUrl).then(
	res => console.log(res), 
	err => console.error(err)
); // Error: 404
```

- 비동기 처리에서 발생한 에러는 catch 메서드를 사용해 처리할 수도 있다.
    - then 메서드 내부에서 발생한 에러까지 모두 캐치할 수 있다.

```jsx
const wrongUrl = 'https://jsonplaceholder.typicode.com/XXX/1';

promiseGet(wrongUrl).then(
	res => console.log(res)
).catch(err => console.error(err));
// Error: 404

// then 메서드 내부 에러 캐치 예시
promiseGet(wrongUrl).then(
	res => console.xxx(res)
).catch(err => console.error(err));
// TypeError: console.xxx is not a function
```

<aside>
💡 에러 처리는 then 메서드의 두 번째 콜백 함수를 사용하는 것보다 catch 메서드를 사용하는 것이 더 가독성이 좋고 명확하다.

</aside># 45장 - 프로미스

## 비동기 처리를 위한 콜백 패턴의 단점

### 콜백 헬 발생

- 비동기 함수의 처리 결과에 대한 후속 처리는 콜백 함수로 하는 것이 일반적이다.
- 비동기 함수의 후속 처리 결과를 가지고 또다시 비동기 함수를 호출한다면 콜백 함수의 중첩도가 높아지는 **콜백 헬**이 발생한다.

```jsx
// 콜백 헬 예시
get('/step1', a => {
	get(`/step2/${a}`, b => {
			get(`/step3/${b}`, c => {
				get(`/step4/${c}`, d => {
					console.log(d);
			})
		})
	})
})
```

### 에러 처리의 한계

- 비동기 처리를 위한 콜백 패턴의 문제점 중에 가장 심각한 것은 에러 처리가 곤란하다는 것이다.

```jsx
// catch 블록에서 에러를 캐치하지 못한다.
try {
	setTimeout(() => {throw new Erro('Error!');}, 1000);
} catch(e) {
	console.error('캐치한 에러', e);
}
```

- setTimeout 함수의 콜백 함수가 실행될 때 setTimeout 함수는 이미 콜 스택에서 제거된 상태다.
    
    이것은 setTimeout 함수의 콜백 함수를 호출한 것이 setTimeout함수가 아니라는 것을 의미한다.
    
- 에러는 호출자 방향으로 전파된다.
- 따라서 setTimeout 함수의 콜백 함수가 발생시킨 에러는 catch 블록에서 캐치되지 않는다.

<aside>
💡 위와 같은 문제를 극복하기 위해 ES6에서 Promise가 도입되었다.

</aside>

## 프로미스의 생성

- new 연산자와 함께 Promise 객체를 생성하여 사용한다.
- 인자로 비동기 처리를 수행할 콜백함수를 받는다.
- 콜백함수의 인자로 resolve와 reject 함수를 받는다.
- resolve 함수는 비동기 처리가 성공하면 결과를 인수로 전달하여 호출하고
- reject 함수는 비동기 처리가 실패하면 에러를 인수로 전달하면서 호출한다.

```jsx
const promise = new Promise((resolve, reject) => {
	if(/* 비동기 처리 성공*/) {
		resolve('result');
	} else { /* 비동기 처리 실패 */
		reject('failure reason');
	}
});
```

### 프로미스의 상태 정보

| 상태 | 의미 | 상태 변경 조건 |
| --- | --- | --- |
| pending | 비동기 처리가 아직 수행되지 않은 상태 | 프로미스가 생성된 직후 기본 상태 |
| fulfilled | 비동기 처리가 수행된 상태(성공) | resolve함수 호출 |
| rejected | 비동기 처리가 수행된 상태(실패) | reject 함수 호출 |
| settled | pending이 아닌 비동기 처리가 수행된 상태 | fulfilled나 rejected된 상태 |
- 비동기 처리 성공 : resolve 함수를 호출해 프로미스를 fulfilled상태로 변경
- 비동기 처리 실패 : reject 함수를 호출해 프로미스를 rejected 상태로 변경

<aside>
💡 프로미스는 비동기 처리 상태와 처리 결과를 관리하는 객체다.

</aside>

## 프로미스의 후속 처리 메서드

- 프로미스의 비동기 처리 상태가 변화하면 이에 따른 후속 처리를 해야 한다.
- 프로미스의 비동기 처리 상태가 변화하면 후속 처리 메서드에 인수로 전달한 콜백 함수가 선택적으로 호출된다.
- 후속 처리 메서드의 콜백 함수에 프로미스 처리 결과가 인수로 전달된다.

### Promise.prototype.then

- then 메서드는 두 개의 콜백 함수를 인수로 전달받는다.
- 첫 번째 콜백 함수는 비동기 처리가 성공했을 때 호출되는 성공 처리 콜백함수
- 두 번째 콜백 함수는 비동기 처리가 실패했을 때 호출되는 실패 처리 콜백함수
- then 메서드는 프로미스를 반환한다.

### Promise.prototype.catch

- catch 메서드는 한 개의 콜백  함수를 인수로 전달받는다.
- catch메서드의 콜백함수는 프로미스가 rejected 상태인 경우만 호출된다.
- catch 메서드는 프로미스를 반환한다.

### Promise.prototype.finally

- finally 메서드는 한 개의 콜백 함수를 인자로 전달받는다.
- finally 메서드의 콜백 함수는 프로미스의 성공(fulfiled) 또는 실패(rejected)와 상관없이 무조건 한 번 호출된다.
- finally 메서드는 프로미스의 상태와 상관없이 공통적으로 수행해야 할 일이 있을 때 유용하다
- finally 메서드는 프로미스를 반환한다.

## 프로미스의 에러 처리

- 비동기 처리에서 발생한 에러는 then메서드의 두 번째 콜백 함수로 처리할 수 있다.

```jsx
const wrongUrl = 'https://jsonplaceholder.typicode.com/XXX/1';

promiseGet(wrongUrl).then(
	res => console.log(res), 
	err => console.error(err)
); // Error: 404
```

- 비동기 처리에서 발생한 에러는 catch 메서드를 사용해 처리할 수도 있다.
    - then 메서드 내부에서 발생한 에러까지 모두 캐치할 수 있다.

```jsx
const wrongUrl = 'https://jsonplaceholder.typicode.com/XXX/1';

promiseGet(wrongUrl).then(
	res => console.log(res)
).catch(err => console.error(err));
// Error: 404

// then 메서드 내부 에러 캐치 예시
promiseGet(wrongUrl).then(
	res => console.xxx(res)
).catch(err => console.error(err));
// TypeError: console.xxx is not a function
```

<aside>
💡 에러 처리는 then 메서드의 두 번째 콜백 함수를 사용하는 것보다 catch 메서드를 사용하는 것이 더 가독성이 좋고 명확하다.

</aside>
